ERROR:cogs.profile_commands:Error in profile creation: 404 Not Found (error code: 10062): Unknown interaction
2025-04-22 06:12:47 ERROR    discord.app_commands.tree Ignoring exception in command 'profile'
Traceback (most recent call last):
  File "/home/runner/workspace/cogs/profile_commands.py", line 75, in profile
    await interaction.response.send_message("Check your DMs to complete profile creation!", ephemeral=True)
  File "/home/runner/workspace/.pythonlibs/lib/python3.11/site-packages/discord/interactions.py", line 1004, in send_message
    response = await adapter.create_interaction_response(
               ^^^^^^^^^^^^^^^^^^^^^^^^^^^^^^^^^^^^^^^^^^
  File "/home/runner/workspace/.pythonlibs/lib/python3.11/site-packages/discord/webhook/async_.py", line 224, in request
    raise NotFound(response, data)
discord.errors.NotFound: 404 Not Found (error code: 10062): Unknown interaction

During handling of the above exception, another exception occurred:

Traceback (most recent call last):
  File "/home/runner/workspace/.pythonlibs/lib/python3.11/site-packages/discord/app_commands/commands.py", line 857, in _do_call
    return await self._callback(self.binding, interaction, **params)  # type: ignore
           ^^^^^^^^^^^^^^^^^^^^^^^^^^^^^^^^^^^^^^^^^^^^^^^^^^^^^^^^^
  File "/home/runner/workspace/cogs/profile_commands.py", line 91, in profile
    await interaction.response.send_message("An error occurred. Please try again.", ephemeral=True)
  File "/home/runner/workspace/.pythonlibs/lib/python3.11/site-packages/discord/interactions.py", line 1004, in send_message
    response = await adapter.create_interaction_response(
               ^^^^^^^^^^^^^^^^^^^^^^^^^^^^^^^^^^^^^^^^^^
  File "/home/runner/workspace/.pythonlibs/lib/python3.11/site-packages/discord/webhook/async_.py", line 226, in request
    raise HTTPException(response, data)
discord.errors.HTTPException: 400 Bad Request (error code: 40060): Interaction has already been acknowledged.

The above exception was the direct cause of the following exception:

Traceback (most recent call last):
  File "/home/runner/workspace/.pythonlibs/lib/python3.11/site-packages/discord/app_commands/tree.py", line 1310, in _call
    await command._invoke_with_namespace(interaction, namespace)
  File "/home/runner/workspace/.pythonlibs/lib/python3.11/site-packages/discord/app_commands/commands.py", line 883, in _invoke_with_namespace
    return await self._do_call(interaction, transformed_values)
           ^^^^^^^^^^^^^^^^^^^^^^^^^^^^^^^^^^^^^^^^^^^^^^^^^^^^
  File "/home/runner/workspace/.pythonlibs/lib/python3.11/site-packages/discord/app_commands/commands.py", line 876, in _do_call
    raise CommandInvokeError(self, e) from e
discord.app_commands.errors.CommandInvokeError: Command 'profile' raised an exception: HTTPException: 400 Bad Request (error code: 40060): Interaction has already been acknowledged.
ERROR:discord.app_commands.tree:Ignoring exception in command 'profile'
Traceback (most recent call last):
  File "/home/runner/workspace/cogs/profile_commands.py", line 75, in profile
    await interaction.response.send_message("Check your DMs to complete profile creation!", ephemeral=True)
  File "/home/runner/workspace/.pythonlibs/lib/python3.11/site-packages/discord/interactions.py", line 1004, in send_message
    response = await adapter.create_interaction_response(
               ^^^^^^^^^^^^^^^^^^^^^^^^^^^^^^^^^^^^^^^^^^
  File "/home/runner/workspace/.pythonlibs/lib/python3.11/site-packages/discord/webhook/async_.py", line 224, in request
    raise NotFound(response, data)
discord.errors.NotFound: 404 Not Found (error code: 10062): Unknown interaction

During handling of the above exception, another exception occurred:

Traceback (most recent call last):
  File "/home/runner/workspace/.pythonlibs/lib/python3.11/site-packages/discord/app_commands/commands.py", line 857, in _do_call
    return await self._callback(self.binding, interaction, **params)  # type: ignore
           ^^^^^^^^^^^^^^^^^^^^^^^^^^^^^^^^^^^^^^^^^^^^^^^^^^^^^^^^^
  File "/home/runner/workspace/cogs/profile_commands.py", line 91, in profile
    await interaction.response.send_message("An error occurred. Please try again.", ephemeral=True)
  File "/home/runner/workspace/.pythonlibs/lib/python3.11/site-packages/discord/interactions.py", line 1004, in send_message
    response = await adapter.create_interaction_response(
               ^^^^^^^^^^^^^^^^^^^^^^^^^^^^^^^^^^^^^^^^^^
  File "/home/runner/workspace/.pythonlibs/lib/python3.11/site-packages/discord/webhook/async_.py", line 226, in request
    raise HTTPException(response, data)
discord.errors.HTTPException: 400 Bad Request (error code: 40060): Interaction has already been acknowledged.

The above exception was the direct cause of the following exception:

Traceback (most recent call last):
  File "/home/runner/workspace/.pythonlibs/lib/python3.11/site-packages/discord/app_commands/tree.py", line 1310, in _call
    await command._invoke_with_namespace(interaction, namespace)
  File "/home/runner/workspace/.pythonlibs/lib/python3.11/site-packages/discord/app_commands/commands.py", line 883, in _invoke_with_namespace
    return await self._do_call(interaction, transformed_values)
           ^^^^^^^^^^^^^^^^^^^^^^^^^^^^^^^^^^^^^^^^^^^^^^^^^^^^
  File "/home/runner/workspace/.pythonlibs/lib/python3.11/site-packages/discord/app_commands/commands.py", line 876, in _do_call
    raise CommandInvokeError(self, e) from e
discord.app_commands.errors.CommandInvokeError: Command 'profile' raised an exception: HTTPException: 400 Bad Request (error code: 40060): Interaction has already been acknowledged.
