.
INFO:discord.gateway:Shard ID None has connected to Gateway (Session ID: f6ae7ea529a11248f7c75367e9c9ffc7).
INFO:bot:Bot is ready! Logged in as Shopify_bot#7022 (ID: 1363474227583254558)
INFO:bot:Connected to 1 guilds
2025-04-22 06:14:19 ERROR    discord.app_commands.tree Ignoring exception in command 'start'
Traceback (most recent call last):
  File "/home/runner/workspace/.pythonlibs/lib/python3.11/site-packages/discord/app_commands/commands.py", line 857, in _do_call
    return await self._callback(self.binding, interaction, **params)  # type: ignore
           ^^^^^^^^^^^^^^^^^^^^^^^^^^^^^^^^^^^^^^^^^^^^^^^^^^^^^^^^^
  File "/home/runner/workspace/cogs/profile_commands.py", line 45, in start
    await interaction.response.send_message(embed=embed, ephemeral=True)
  File "/home/runner/workspace/.pythonlibs/lib/python3.11/site-packages/discord/interactions.py", line 1004, in send_message
    response = await adapter.create_interaction_response(
               ^^^^^^^^^^^^^^^^^^^^^^^^^^^^^^^^^^^^^^^^^^
  File "/home/runner/workspace/.pythonlibs/lib/python3.11/site-packages/discord/webhook/async_.py", line 224, in request
    raise NotFound(response, data)
discord.errors.NotFound: 404 Not Found (error code: 10062): Unknown interaction

The above exception was the direct cause of the following exception:

Traceback (most recent call last):
  File "/home/runner/workspace/.pythonlibs/lib/python3.11/site-packages/discord/app_commands/tree.py", line 1310, in _call
    await command._invoke_with_namespace(interaction, namespace)
  File "/home/runner/workspace/.pythonlibs/lib/python3.11/site-packages/discord/app_commands/commands.py", line 883, in _invoke_with_namespace
    return await self._do_call(interaction, transformed_values)
           ^^^^^^^^^^^^^^^^^^^^^^^^^^^^^^^^^^^^^^^^^^^^^^^^^^^^
  File "/home/runner/workspace/.pythonlibs/lib/python3.11/site-packages/discord/app_commands/commands.py", line 876, in _do_call
    raise CommandInvokeError(self, e) from e
discord.app_commands.errors.CommandInvokeError: Command 'start' raised an exception: NotFound: 404 Not Found (error code: 10062): Unknown interaction
ERROR:discord.app_commands.tree:Ignoring exception in command 'start'
Traceback (most recent call last):
  File "/home/runner/workspace/.pythonlibs/lib/python3.11/site-packages/discord/app_commands/commands.py", line 857, in _do_call
    return await self._callback(self.binding, interaction, **params)  # type: ignore
           ^^^^^^^^^^^^^^^^^^^^^^^^^^^^^^^^^^^^^^^^^^^^^^^^^^^^^^^^^
  File "/home/runner/workspace/cogs/profile_commands.py", line 45, in start
    await interaction.response.send_message(embed=embed, ephemeral=True)
  File "/home/runner/workspace/.pythonlibs/lib/python3.11/site-packages/discord/interactions.py", line 1004, in send_message
    response = await adapter.create_interaction_response(
               ^^^^^^^^^^^^^^^^^^^^^^^^^^^^^^^^^^^^^^^^^^
  File "/home/runner/workspace/.pythonlibs/lib/python3.11/site-packages/discord/webhook/async_.py", line 224, in request
    raise NotFound(response, data)
discord.errors.NotFound: 404 Not Found (error code: 10062): Unknown interaction

The above exception was the direct cause of the following exception:

Traceback (most recent call last):
  File "/home/runner/workspace/.pythonlibs/lib/python3.11/site-packages/discord/app_commands/tree.py", line 1310, in _call
    await command._invoke_with_namespace(interaction, namespace)
  File "/home/runner/workspace/.pythonlibs/lib/python3.11/site-packages/discord/app_commands/commands.py", line 883, in _invoke_with_namespace
    return await self._do_call(interaction, transformed_values)
           ^^^^^^^^^^^^^^^^^^^^^^^^^^^^^^^^^^^^^^^^^^^^^^^^^^^^
  File "/home/runner/workspace/.pythonlibs/lib/python3.11/site-packages/discord/app_commands/commands.py", line 876, in _do_call
    raise CommandInvokeError(self, e) from e
discord.app_commands.errors.CommandInvokeError: Command 'start' raised an exception: NotFound: 404 Not Found (error code: 10062): Unknown interaction
INFO:werkzeug:172.31.128.108 - - [22/Apr/2025 06:14:19] "GET / HTTP/1.1" 200 -
ERROR:cogs.profile_commands:Error creating DM channel: 400 Bad Request (error code: 40003): You are opening direct messages too fast.
ERROR:cogs.profile_commands:Error in profile creation: This interaction has already been responded to before
ERROR:cogs.profile_commands:Error in profile creation: 400 Bad Request (error code: 40060): Interaction has already been acknowledged.
2025-04-22 06:14:26 ERROR    discord.app_commands.tree Ignoring exception in command 'profile'
Traceback (most recent call last):
  File "/home/runner/workspace/cogs/profile_commands.py", line 55, in profile
    dm_channel = await interaction.user.create_dm()
                 ^^^^^^^^^^^^^^^^^^^^^^^^^^^^^^^^^^
  File "/home/runner/workspace/.pythonlibs/lib/python3.11/site-packages/discord/user.py", line 569, in create_dm
    data: DMChannelPayload = await state.http.start_private_message(self.id)
                             ^^^^^^^^^^^^^^^^^^^^^^^^^^^^^^^^^^^^^^^^^^^^^^^
  File "/home/runner/workspace/.pythonlibs/lib/python3.11/site-packages/discord/http.py", line 762, in request
    raise HTTPException(response, data)
discord.errors.HTTPException: 400 Bad Request (error code: 40003): You are opening direct messages too fast.

During handling of the above exception, another exception occurred:

Traceback (most recent call last):
  File "/home/runner/workspace/cogs/profile_commands.py", line 61, in profile
    await interaction.response.send_message("An error occurred while creating DM channel. Please try again.", ephemeral=True)
  File "/home/runner/workspace/.pythonlibs/lib/python3.11/site-packages/discord/interactions.py", line 1004, in send_message
    response = await adapter.create_interaction_response(
               ^^^^^^^^^^^^^^^^^^^^^^^^^^^^^^^^^^^^^^^^^^
  File "/home/runner/workspace/.pythonlibs/lib/python3.11/site-packages/discord/webhook/async_.py", line 226, in request
    raise HTTPException(response, data)
discord.errors.HTTPException: 400 Bad Request (error code: 40060): Interaction has already been acknowledged.

During handling of the above exception, another exception occurred:

Traceback (most recent call last):
  File "/home/runner/workspace/.pythonlibs/lib/python3.11/site-packages/discord/app_commands/commands.py", line 857, in _do_call
    return await self._callback(self.binding, interaction, **params)  # type: ignore
           ^^^^^^^^^^^^^^^^^^^^^^^^^^^^^^^^^^^^^^^^^^^^^^^^^^^^^^^^^
  File "/home/runner/workspace/cogs/profile_commands.py", line 93, in profile
    await interaction.response.send_message("An error occurred. Please try again.", ephemeral=True)
  File "/home/runner/workspace/.pythonlibs/lib/python3.11/site-packages/discord/interactions.py", line 1004, in send_message
    response = await adapter.create_interaction_response(
               ^^^^^^^^^^^^^^^^^^^^^^^^^^^^^^^^^^^^^^^^^^
  File "/home/runner/workspace/.pythonlibs/lib/python3.11/site-packages/discord/webhook/async_.py", line 226, in request
    raise HTTPException(response, data)
discord.errors.HTTPException: 400 Bad Request (error code: 40060): Interaction has already been acknowledged.

The above exception was the direct cause of the following exception:

Traceback (most recent call last):
  File "/home/runner/workspace/.pythonlibs/lib/python3.11/site-packages/discord/app_commands/tree.py", line 1310, in _call
    await command._invoke_with_namespace(interaction, namespace)
  File "/home/runner/workspace/.pythonlibs/lib/python3.11/site-packages/discord/app_commands/commands.py", line 883, in _invoke_with_namespace
    return await self._do_call(interaction, transformed_values)
           ^^^^^^^^^^^^^^^^^^^^^^^^^^^^^^^^^^^^^^^^^^^^^^^^^^^^
  File "/home/runner/workspace/.pythonlibs/lib/python3.11/site-packages/discord/app_commands/commands.py", line 876, in _do_call
    raise CommandInvokeError(self, e) from e
discord.app_commands.errors.CommandInvokeError: Command 'profile' raised an exception: HTTPException: 400 Bad Request (error code: 40060): Interaction has already been acknowledged.
ERROR:discord.app_commands.tree:Ignoring exception in command 'profile'
Traceback (most recent call last):
  File "/home/runner/workspace/cogs/profile_commands.py", line 55, in profile
    dm_channel = await interaction.user.create_dm()
                 ^^^^^^^^^^^^^^^^^^^^^^^^^^^^^^^^^^
  File "/home/runner/workspace/.pythonlibs/lib/python3.11/site-packages/discord/user.py", line 569, in create_dm
    data: DMChannelPayload = await state.http.start_private_message(self.id)
                             ^^^^^^^^^^^^^^^^^^^^^^^^^^^^^^^^^^^^^^^^^^^^^^^
  File "/home/runner/workspace/.pythonlibs/lib/python3.11/site-packages/discord/http.py", line 762, in request
    raise HTTPException(response, data)
discord.errors.HTTPException: 400 Bad Request (error code: 40003): You are opening direct messages too fast.

During handling of the above exception, another exception occurred:

Traceback (most recent call last):
  File "/home/runner/workspace/cogs/profile_commands.py", line 61, in profile
    await interaction.response.send_message("An error occurred while creating DM channel. Please try again.", ephemeral=True)
  File "/home/runner/workspace/.pythonlibs/lib/python3.11/site-packages/discord/interactions.py", line 1004, in send_message
    response = await adapter.create_interaction_response(
               ^^^^^^^^^^^^^^^^^^^^^^^^^^^^^^^^^^^^^^^^^^
  File "/home/runner/workspace/.pythonlibs/lib/python3.11/site-packages/discord/webhook/async_.py", line 226, in request
    raise HTTPException(response, data)
discord.errors.HTTPException: 400 Bad Request (error code: 40060): Interaction has already been acknowledged.

During handling of the above exception, another exception occurred:

Traceback (most recent call last):
  File "/home/runner/workspace/.pythonlibs/lib/python3.11/site-packages/discord/app_commands/commands.py", line 857, in _do_call
    return await self._callback(self.binding, interaction, **params)  # type: ignore
           ^^^^^^^^^^^^^^^^^^^^^^^^^^^^^^^^^^^^^^^^^^^^^^^^^^^^^^^^^
  File "/home/runner/workspace/cogs/profile_commands.py", line 93, in profile
    await interaction.response.send_message("An error occurred. Please try again.", ephemeral=True)
  File "/home/runner/workspace/.pythonlibs/lib/python3.11/site-packages/discord/interactions.py", line 1004, in send_message
    response = await adapter.create_interaction_response(
               ^^^^^^^^^^^^^^^^^^^^^^^^^^^^^^^^^^^^^^^^^^
  File "/home/runner/workspace/.pythonlibs/lib/python3.11/site-packages/discord/webhook/async_.py", line 226, in request
    raise HTTPException(response, data)
discord.errors.HTTPException: 400 Bad Request (error code: 40060): Interaction has already been acknowledged.

The above exception was the direct cause of the following exception:

Traceback (most recent call last):
  File "/home/runner/workspace/.pythonlibs/lib/python3.11/site-packages/discord/app_commands/tree.py", line 1310, in _call
    await command._invoke_with_namespace(interaction, namespace)
  File "/home/runner/workspace/.pythonlibs/lib/python3.11/site-packages/discord/app_commands/commands.py", line 883, in _invoke_with_namespace
    return await self._do_call(interaction, transformed_values)
           ^^^^^^^^^^^^^^^^^^^^^^^^^^^^^^^^^^^^^^^^^^^^^^^^^^^^
  File "/home/runner/workspace/.pythonlibs/lib/python3.11/site-packages/discord/app_commands/commands.py", line 876, in _do_call
    raise CommandInvokeError(self, e) from e
discord.app_commands.errors.CommandInvokeError: Command 'profile' raised an exception: HTTPException: 400 Bad Request (error code: 40060): Interaction has already been acknowledged.
